<!doctype html>
<html lang="en">

	<head>
		<meta charset="utf-8">

		<title>excepciones python</title>

		<meta name="description" content="A framework for easily creating beautiful presentations using HTML">
		<meta name="author" content="Hakim El Hattab">

		<meta name="apple-mobile-web-app-capable" content="yes">
		<meta name="apple-mobile-web-app-status-bar-style" content="black-translucent">

		<meta name="viewport" content="width=device-width, initial-scale=1.0, maximum-scale=1.0, user-scalable=no">

		<link rel="stylesheet" href="css/reveal.css">
		<link rel="stylesheet" href="css/theme/black.css" id="theme">

		<!-- Theme used for syntax highlighting of code -->
		<link rel="stylesheet" href="lib/css/zenburn.css">

		<!-- Printing and PDF exports -->
		<script>
			var link = document.createElement( 'link' );
			link.rel = 'stylesheet';
			link.type = 'text/css';
			link.href = window.location.search.match( /print-pdf/gi ) ? 'css/print/pdf.css' : 'css/print/paper.css';
			document.getElementsByTagName( 'head' )[0].appendChild( link );
		</script>

		<!--[if lt IE 9]>
		<script src="lib/js/html5shiv.js"></script>
		<![endif]-->
	</head>

	<body>

		<div class="reveal">

			<!-- Any section element inside of this container is displayed as a slide -->
			<div class="slides">
				<section>
					<h1>Errores y Excepciones en</h1>
					<h2><img src="img/pyico.png" alt="" width="20%"></h2>
					<p>El tipico try / catch pero en python</p>
					<p>
						<small>por <a href="https://github.com/MiguelRodriguezR">Miguel Rodriguez</a></small>
					</p>
				</section>

				<section>
					<p>
						Los errores de sintaxis, también conocidos como errores de parsing, son quizás el tipo más común de queja que obtienes mientras todavía estás aprendiendo Python:
					</p>
					<pre><code class="hljs" data-trim contenteditable>
						>>> while True print 'Hello world'
						  File "stdin", line 1
						    while True print 'Hello world'
						                   ^
						SyntaxError: invalid syntax
					</code></pre>
					<p>Error cortesía de <a href="https://docs.python.org/2/tutorial/errors.html">Python Docs</a>.</p>

				</section>

				<section>
					<p>
						El analizador repite la línea ofensiva y muestra una pequeña "flecha" <strong style="color:red"> ^ </strong> que apunta al primer punto en la línea donde se detectó el error.  El nombre del archivo y el número de línea se imprimen para que sepa dónde buscar en caso de que la entrada provenga de un script.
					</p>
				</section>

				<section>
					<p>pero aun si las sentencias son sintacticamente correctas se puede causar un error y es ahi donde entran en juego las excepciones:</p>
					<pre><code class="hljs" data-trim contenteditable>
>>> while True:
...     try:
...         x = int(input("ingrese un numero: "))
...         break
...     except ValueError:
...         print ("Oops! no es numero. intente de nuevo...")
...
					</code></pre>
				</section>

				<section>
					<p>asi funciona el ciclo de vida de una excepción.</p>
					<img src="img/diagrama.png" alt="">
				</section>

				<section>
					<p>Una instrucción try puede tener más de una cláusula except, para especificar manejadores para diferentes excepciones, de la misma manera una cláusula except puede nombrar múltiples excepciones en una tupla:</p>
					<pre><code class="hljs" data-trim contenteditable>
						... except (RuntimeError, TypeError, NameError):
						...     pass
					</code></pre>

				</section>

				<section>
					<p>para acceder al detalle de una excepción tenemos la posibilidad de almacenar la excepción en una variable</p>
					<pre><code class="hljs" data-trim contenteditable>
>>> def this_fails():
...     x = 1/0
...
>>> try:
...     this_fails()
... except ZeroDivisionError as detail:
...     print ('Handling run-time error:', detail)
...
Handling run-time error: integer division or modulo by zero
					</code></pre>
				</section>

				<section>
					<h2>Planteando Excepciones</h2>
					<img src="img/error.jpg" alt="">
				</section>

				<section>
					<p>La declaración raise permite al programador forzar una excepción especificada para que ocurra.</p>
					<pre><code class="hljs" data-trim contenteditable>
						>>> raise NameError('HiThere')
						Traceback (most recent call last):
						  File "stdin", line 1, in module
						NameError: HiThere
					</code></pre>

				</section>

				<section>
					<p>Si necesita determinar si se generó una excepción pero no tiene la intención de manejarla, entonces hay una manera mejor de hacerlo</p>
					<pre><code class="hljs" data-trim contenteditable>
>>> try:
...     raise NameError('Hola')
... except NameError:
...     print ('Una excepción ocurrió!')
...     raise
...
Una excepción ocurrió!
Traceback (most recent call last):
  File "stdin", line 2, in module
NameError: Hola
					</code></pre>
				</section>

				<section>
					<h2>Excepciones definidas por el usuario</h2>
					<img src="img/bear.gif" alt="">
				</section>


				<section>
					<p> Por lo general, las excepciones se deben derivar de la clase <strong>Exception</strong></p>
					<pre><code class="hljs" data-trim contenteditable>
						>>> class MyError(Exception):
						...     def __init__(self, value):
						...         self.value = value
						...     def __str__(self):
						...         return repr(self.value)
						...
						>>> try:
						...     raise MyError(2*2)
						... except MyError as e:
						...     print ('My exception occurred, value:', e.value)
						...
						My exception occurred, value: 4
					</code></pre>
				</section>

				<section>
					<p>por ultimo pero no menos importante las Clean-up Actions </p>
					<pre><code class="hljs" data-trim contenteditable>
>>> def divide(x, y):
...     try:
...         result = x / y
...     except ZeroDivisionError:
...         print ("division by zero!")
...     else:
...         print ("result is", result)
...     finally:
...         print ("executing finally clause")
>>> divide(2, 1)
result is 2
executing finally clause
>>> divide(2, 0)
division by zero!
executing finally clause
>>> divide("2", "1")
executing finally clause
Traceback (most recent call last):
  File "stdin", line 1, in module
  File "stdin", line 3, in divide
TypeError: unsupported operand type(s) for /: 'str' and 'str'
					</code></pre>

				</section>

				<section data-background="img/oso.gif">
					<div style="background-color: rgba(0, 0, 0, 0.5); color: #fff; padding: 20px;">
						<h2>... y eso es todo!</h2>
						<a href="https://github.com/MiguelRodriguezR">https://github.com/MiguelRodriguezR</a>
					</div>
				</section>

			</div>

		</div>

		<script src="lib/js/head.min.js"></script>
		<script src="js/reveal.js"></script>

		<script>

			// More info https://github.com/hakimel/reveal.js#configuration
			Reveal.initialize({
				controls: true,
				progress: true,
				history: true,
				center: true,

				transition: 'slide', // none/fade/slide/convex/concave/zoom

				// More info https://github.com/hakimel/reveal.js#dependencies
				dependencies: [
					{ src: 'lib/js/classList.js', condition: function() { return !document.body.classList; } },
					{ src: 'plugin/markdown/marked.js', condition: function() { return !!document.querySelector( '[data-markdown]' ); } },
					{ src: 'plugin/markdown/markdown.js', condition: function() { return !!document.querySelector( '[data-markdown]' ); } },
					{ src: 'plugin/highlight/highlight.js', async: true, callback: function() { hljs.initHighlightingOnLoad(); } },
					{ src: 'plugin/search/search.js', async: true },
					{ src: 'plugin/zoom-js/zoom.js', async: true },
					{ src: 'plugin/notes/notes.js', async: true }
				]
			});

		</script>

	</body>
</html>
